Workbook

Sheet Trips
A1: Trip_ID | B1: Date | C1: Total_Spent | D1: Time_Spent (min) | E1: Arrival_Time | F1: Busy | G1: Total_Items | H1: Total_Kept | I1: Total_To_Sell | J1: Total_Discarded | K1: Cost_Per_Sellable_Item | L1: Validation
A2: =IF(B2="","",ROW()-1) -> 1 | B2: 45937 | C2: 20.93 | D2: 88 | E2: 0.44930556 | F2: Low | G2: 17 | H2: 2 | I2: 12 | J2: 3 | K2: =IF(I2="","",IF(I2=0,"No sellable items",C2/I2)) -> 1.7441667 | L2: =IF(G2="","",IF(G2=H2+I2+J2,"✓","✗ Mismatch")) -> ✓
A3: =IF(B3="","",ROW()-1) -> 2 | B3: 45953 | C3: 18.28 | D3: 124 | E3: 0.39930556 | F3: Low | G3: 16 | H3: 3 | I3: 10 | J3: 3 | K3: =IF(I3="","",IF(I3=0,"No sellable items",C3/I3)) -> 1.828 | L3: =IF(G3="","",IF(G3=H3+I3+J3,"✓","✗ Mismatch")) -> ✓
A4: =IF(B4="","",ROW()-1) -> 3 | B4: 45965 | C4: 46.04 | D4: 60 | E4: 0.44722222 | F4: Medium | G4: 10 | H4: 3 | I4: 4 | J4: 3 | K4: =IF(I4="","",IF(I4=0,"No sellable items",C4/I4)) -> 11.51 | L4: =IF(G4="","",IF(G4=H4+I4+J4,"✓","✗ Mismatch")) -> ✓
A5: =IF(B5="","",ROW()-1) -> 4 | B5: 45983 | C5: 12.55 | D5: 168 | E5: 0.48472222 | F5: Low | G5: 6 | H5: 1 | I5: 4 | J5: 1 | K5: =IF(I5="","",IF(I5=0,"No sellable items",C5/I5)) -> 3.1375 | L5: =IF(G5="","",IF(G5=H5+I5+J5,"✓","✗ Mismatch")) -> ✓
A6: =IF(B6="","",ROW()-1) -> 5 | B6: 46001 | C6: 46.98 | D6: 139 | E6: 0.48333333 | F6: Low | G6: 7 | H6: 1 | I6: 3 | J6: 3 | K6: =IF(I6="","",IF(I6=0,"No sellable items",C6/I6)) -> 15.66 | L6: =IF(G6="","",IF(G6=H6+I6+J6,"✓","✗ Mismatch")) -> ✓
A7: =IF(B7="","",ROW()-1) -> 6 | B7: 46010 | C7: 48.2 | D7: 170 | E7: 0.43333333 | F7: Low | G7: 16 | H7: 2 | I7: 11 | J7: 3 | K7: =IF(I7="","",IF(I7=0,"No sellable items",C7/I7)) -> 4.3818182 | L7: =IF(G7="","",IF(G7=H7+I7+J7,"✓","✗ Mismatch")) -> ✓
A8: =IF(B8="","",ROW()-1) -> 7 | B8: 46020 | C8: 20.55 | D8: 179 | E8: 0.44305556 | F8: Medium | G8: 14 | H8: 2 | I8: 9 | J8: 3 | K8: =IF(I8="","",IF(I8=0,"No sellable items",C8/I8)) -> 2.2833333 | L8: =IF(G8="","",IF(G8=H8+I8+J8,"✓","✗ Mismatch")) -> ✓
A9: =IF(B9="","",ROW()-1) -> 8 | B9: 46031 | C9: 51.49 | D9: 148 | E9: 0.59305556 | F9: Medium | G9: 6 | H9: 0 | I9: 3 | J9: 3 | K9: =IF(I9="","",IF(I9=0,"No sellable items",C9/I9)) -> 17.163333 | L9: =IF(G9="","",IF(G9=H9+I9+J9,"✓","✗ Mismatch")) -> ✓
A10: =IF(B10="","",ROW()-1) -> 9 | B10: 46041 | C10: 11.11 | D10: 176 | E10: 0.46736111 | F10: Medium | G10: 12 | H10: 3 | I10: 8 | J10: 1 | K10: =IF(I10="","",IF(I10=0,"No sellable items",C10/I10)) -> 1.38875 | L10: =IF(G10="","",IF(G10=H10+I10+J10,"✓","✗ Mismatch")) -> ✓
A11: =IF(B11="","",ROW()-1) -> 10 | B11: 46048 | C11: 19.59 | D11: 131 | E11: 0.59444444 | F11: Medium | G11: 12 | H11: 2 | I11: 8 | J11: 2 | K11: =IF(I11="","",IF(I11=0,"No sellable items",C11/I11)) -> 2.44875 | L11: =IF(G11="","",IF(G11=H11+I11+J11,"✓","✗ Mismatch")) -> ✓
A12: =IF(B12="","",ROW()-1) -> 11 | B12: 46056 | C12: 14.5 | D12: 123 | E12: 0.45 | F12: Low | G12: 7 | H12: 1 | I12: 3 | J12: 3 | K12: =IF(I12="","",IF(I12=0,"No sellable items",C12/I12)) -> 4.8333333 | L12: =IF(G12="","",IF(G12=H12+I12+J12,"✓","✗ Mismatch")) -> ✓
A13: =IF(B13="","",ROW()-1) -> 12 | B13: 46067 | C13: 26.08 | D13: 136 | E13: 0.56458333 | F13: Low | G13: 14 | H13: 2 | I13: 9 | J13: 3 | K13: =IF(I13="","",IF(I13=0,"No sellable items",C13/I13)) -> 2.8977778 | L13: =IF(G13="","",IF(G13=H13+I13+J13,"✓","✗ Mismatch")) -> ✓
... A16: =IF(B16="","",ROW()-1) -> 15 | B16: 46092 | C16: 33.35 | D16: 159 | E16: 0.62361111 | F16: Low | G16: 11 | H16: 1 | I16: 6 | J16: 4 | K16: =IF(I16="","",IF(I16=0,"No sellable items",C16/I16)) -> 5.5583333 | L16: =IF(G16="","",IF(G16=H16+I16+J16,"✓","✗ Mismatch")) -> ✓
A17: =IF(B17="","",ROW()-1) | K17: =IF(I17="","",IF(I17=0,"No sellable items",C17/I17)) | L17: =IF(G17="","",IF(G17=H17+I17+J17,"✓","✗ Mismatch"))
A18: =IF(B18="","",ROW()-1) | K18: =IF(I18="","",IF(I18=0,"No sellable items",C18/I18)) | L18: =IF(G18="","",IF(G18=H18+I18+J18,"✓","✗ Mismatch"))
A19: =IF(B19="","",ROW()-1) | K19: =IF(I19="","",IF(I19=0,"No sellable items",C19/I19)) | L19: =IF(G19="","",IF(G19=H19+I19+J19,"✓","✗ Mismatch"))
A20: =IF(B20="","",ROW()-1) | K20: =IF(I20="","",IF(I20=0,"No sellable items",C20/I20)) | L20: =IF(G20="","",IF(G20=H20+I20+J20,"✓","✗ Mismatch"))
A21: =IF(B21="","",ROW()-1) | K21: =IF(I21="","",IF(I21=0,"No sellable items",C21/I21)) | L21: =IF(G21="","",IF(G21=H21+I21+J21,"✓","✗ Mismatch"))
A22: =IF(B22="","",ROW()-1) | K22: =IF(I22="","",IF(I22=0,"No sellable items",C22/I22)) | L22: =IF(G22="","",IF(G22=H22+I22+J22,"✓","✗ Mismatch"))
A23: =IF(B23="","",ROW()-1) | K23: =IF(I23="","",IF(I23=0,"No sellable items",C23/I23)) | L23: =IF(G23="","",IF(G23=H23+I23+J23,"✓","✗ Mismatch"))
A24: =IF(B24="","",ROW()-1) | K24: =IF(I24="","",IF(I24=0,"No sellable items",C24/I24)) | L24: =IF(G24="","",IF(G24=H24+I24+J24,"✓","✗ Mismatch"))
A25: =IF(B25="","",ROW()-1) | K25: =IF(I25="","",IF(I25=0,"No sellable items",C25/I25)) | L25: =IF(G25="","",IF(G25=H25+I25+J25,"✓","✗ Mismatch"))
A26: =IF(B26="","",ROW()-1) | K26: =IF(I26="","",IF(I26=0,"No sellable items",C26/I26)) | L26: =IF(G26="","",IF(G26=H26+I26+J26,"✓","✗ Mismatch"))
A27: =IF(B27="","",ROW()-1) | K27: =IF(I27="","",IF(I27=0,"No sellable items",C27/I27)) | L27: =IF(G27="","",IF(G27=H27+I27+J27,"✓","✗ Mismatch"))
A28: =IF(B28="","",ROW()-1) | K28: =IF(I28="","",IF(I28=0,"No sellable items",C28/I28)) | L28: =IF(G28="","",IF(G28=H28+I28+J28,"✓","✗ Mismatch"))
... A51: =IF(B51="","",ROW()-1) | K51: =IF(I51="","",IF(I51=0,"No sellable items",C51/I51)) | L51: =IF(G51="","",IF(G51=H51+I51+J51,"✓","✗ Mismatch"))

Sheet Items
A1: SKU | B1: Trip_ID | C1: Brand | D1: Size | E1: Gender | F1: Description | G1: Tags | H1: Condition Notes | I1: Category | J1: Status
A2: =IF(C2="","","T"&TEXT(B2,"000")&"I"&TEXT(COUNTIF(B$2:B2,B2),"000")) -> T001I001 | B2: 1 | C2: J.Crew | D2: S/M | E2: F | F2: navy sunglasses | I2: Accessories | J2: Sell
A3: =IF(C3="","","T"&TEXT(B3,"000")&"I"&TEXT(COUNTIF(B$2:B3,B3),"000")) -> T001I002 | B3: 1 | C3: Levi's | D3: XL | E3: F | F3: pink fitted romper | I3: Jumpsuits/Rompers | J3: Sell
A4: =IF(C4="","","T"&TEXT(B4,"000")&"I"&TEXT(COUNTIF(B$2:B4,B4),"000")) -> T001I003 | B4: 1 | C4: Zara | D4: S | E4: M | F4: green joggers | I4: Bottoms | J4: Sell
A5: =IF(C5="","","T"&TEXT(B5,"000")&"I"&TEXT(COUNTIF(B$2:B5,B5),"000")) -> T001I004 | B5: 1 | C5: Patagonia | D5: L | E5: F | F5: purple wrap dress | I5: Dresses | J5: Sell
A6: =IF(C6="","","T"&TEXT(B6,"000")&"I"&TEXT(COUNTIF(B$2:B6,B6),"000")) -> T001I005 | B6: 1 | C6: Deb | D6: S | E6: F | F6: plaid cotton jeans | I6: Bottoms | J6: Sell
A7: =IF(C7="","","T"&TEXT(B7,"000")&"I"&TEXT(COUNTIF(B$2:B7,B7),"000")) -> T001I006 | B7: 1 | C7: Old Navy | D7: XS | E7: F | F7: navy vintage tank top | I7: Tops | J7: Sell
A8: =IF(C8="","","T"&TEXT(B8,"000")&"I"&TEXT(COUNTIF(B$2:B8,B8),"000")) -> T001I007 | B8: 1 | C8: BKE | D8: S | E8: F | F8: striped boho tank top | I8: Tops | J8: Sell
A9: =IF(C9="","","T"&TEXT(B9,"000")&"I"&TEXT(COUNTIF(B$2:B9,B9),"000")) -> T001I008 | B9: 1 | C9: Levi's | D9: 10 | E9: F | F9: green flats | I9: Footwear | J9: Sell
A10: =IF(C10="","","T"&TEXT(B10,"000")&"I"&TEXT(COUNTIF(B$2:B10,B10),"000")) -> T001I009 | B10: 1 | C10: Express | D10: M | E10: F | F10: red vintage jeans | I10: Bottoms | J10: Sell
A11: =IF(C11="","","T"&TEXT(B11,"000")&"I"&TEXT(COUNTIF(B$2:B11,B11),"000")) -> T001I010 | B11: 1 | C11: H&M | D11: L | E11: F | F11: striped denim tank top | I11: Tops | J11: Sell
A12: =IF(C12="","","T"&TEXT(B12,"000")&"I"&TEXT(COUNTIF(B$2:B12,B12),"000")) -> T001I011 | B12: 1 | C12: LOFT | D12: M | E12: M | F12: olive cotton blouse | I12: Tops | J12: Sell
A13: =IF(C13="","","T"&TEXT(B13,"000")&"I"&TEXT(COUNTIF(B$2:B13,B13),"000")) -> T001I012 | B13: 1 | C13: Express | D13: M | E13: F | F13: gray boho dress | I13: Dresses | J13: Sell
... A15: =IF(C15="","","T"&TEXT(B15,"000")&"I"&TEXT(COUNTIF(B$2:B15,B15),"000")) -> T001I014 | B15: 1 | C15: Urban Outfitters | D15: L | E15: F | F15: striped henley | I15: Tops | J15: Keep
A16: =IF(C16="","","T"&TEXT(B16,"000")&"I"&TEXT(COUNTIF(B$2:B16,B16),"000")) -> T001I015 | B16: 1 | C16: Other | D16: S | E16: M | F16: striped vintage cami | H16: stretched out | I16: Tops | J16: Discard
A17: =IF(C17="","","T"&TEXT(B17,"000")&"I"&TEXT(COUNTIF(B$2:B17,B17),"000")) -> T001I016 | B17: 1 | C17: Nike | D17: M | E17: M | F17: blue button-down shirt | H17: bleach mark | I17: Tops | J17: Discard
A18: =IF(C18="","","T"&TEXT(B18,"000")&"I"&TEXT(COUNTIF(B$2:B18,B18),"000")) -> T001I017 | B18: 1 | C18: Express | D18: M | E18: F | F18: coral y2k tank top | H18: bleach mark | I18: Tops | J18: Discard
A19: =IF(C19="","","T"&TEXT(B19,"000")&"I"&TEXT(COUNTIF(B$2:B19,B19),"000")) -> T002I001 | B19: 2 | C19: Gap | D19: M | E19: F | F19: plaid bodycon dress | I19: Dresses | J19: Sell
A20: =IF(C20="","","T"&TEXT(B20,"000")&"I"&TEXT(COUNTIF(B$2:B20,B20),"000")) -> T002I002 | B20: 2 | C20: Adidas | D20: L | E20: F | F20: coral long sleeve boho shirt | I20: Tops | J20: Sell
A21: =IF(C21="","","T"&TEXT(B21,"000")&"I"&TEXT(COUNTIF(B$2:B21,B21),"000")) -> T002I003 | B21: 2 | C21: Other | D21: S | E21: F | F21: black denim blouse | I21: Tops | J21: Sell
A22: =IF(C22="","","T"&TEXT(B22,"000")&"I"&TEXT(COUNTIF(B$2:B22,B22),"000")) -> T002I004 | B22: 2 | C22: SO Clothing | D22: XS | E22: F | F22: brown bodycon dress | I22: Dresses | J22: Sell
A23: =IF(C23="","","T"&TEXT(B23,"000")&"I"&TEXT(COUNTIF(B$2:B23,B23),"000")) -> T002I005 | B23: 2 | C23: Hollister | D23: 7 | E23: F | F23: striped flats | I23: Footwear | J23: Sell
A24: =IF(C24="","","T"&TEXT(B24,"000")&"I"&TEXT(COUNTIF(B$2:B24,B24),"000")) -> T002I006 | B24: 2 | C24: Nike | D24: M/L | E24: F | F24: pink athletic scarf | I24: Accessories | J24: Sell
A25: =IF(C25="","","T"&TEXT(B25,"000")&"I"&TEXT(COUNTIF(B$2:B25,B25),"000")) -> T002I007 | B25: 2 | C25: Victoria's Secret | D25: M | E25: F | F25: green oversized cami | I25: Tops | J25: Sell
A26: =IF(C26="","","T"&TEXT(B26,"000")&"I"&TEXT(COUNTIF(B$2:B26,B26),"000")) -> T002I008 | B26: 2 | C26: J.Crew | D26: L | E26: F | F26: white mini dress | I26: Dresses | J26: Sell
A27: =IF(C27="","","T"&TEXT(B27,"000")&"I"&TEXT(COUNTIF(B$2:B27,B27),"000")) -> T002I009 | B27: 2 | C27: Apt. 9 | D27: XS | E27: F | F27: brown boho romper | I27: Jumpsuits/Rompers | J27: Sell
A28: =IF(C28="","","T"&TEXT(B28,"000")&"I"&TEXT(COUNTIF(B$2:B28,B28),"000")) -> T002I010 | B28: 2 | C28: Levi's | D28: M | E28: F | F28: pink cotton dress | I28: Dresses | J28: Sell
A29: =IF(C29="","","T"&TEXT(B29,"000")&"I"&TEXT(COUNTIF(B$2:B29,B29),"000")) -> T002I011 | B29: 2 | C29: Free People | D29: M | E29: F | F29: tan lace jeans | I29: Bottoms | J29: Keep
A30: =IF(C30="","","T"&TEXT(B30,"000")&"I"&TEXT(COUNTIF(B$2:B30,B30),"000")) -> T002I012 | B30: 2 | C30: Deb | D30: L | E30: M | F30: gray fitted romper | I30: Jumpsuits/Rompers | J30: Keep
... A33: =IF(C33="","","T"&TEXT(B33,"000")&"I"&TEXT(COUNTIF(B$2:B33,B33),"000")) -> T002I015 | B33: 2 | C33: Other | D33: S | E33: F | F33: red windbreaker | I33: Coats/Jackets | J33: Discard
A34: =IF(C34="","","T"&TEXT(B34,"000")&"I"&TEXT(COUNTIF(B$2:B34,B34),"000")) -> T002I016 | B34: 2 | C34: Free People | D34: S | E34: M | F34: tan cargo pants | H34: hole in seam | I34: Bottoms | J34: Discard
A35: =IF(C35="","","T"&TEXT(B35,"000")&"I"&TEXT(COUNTIF(B$2:B35,B35),"000")) -> T003I001 | B35: 3 | C35: Free People | D35: S | E35: M | F35: purple long sleeve fitted shirt | I35: Tops | J35: Sell
A36: =IF(C36="","","T"&TEXT(B36,"000")&"I"&TEXT(COUNTIF(B$2:B36,B36),"000")) -> T003I002 | B36: 3 | C36: Forever 21 | D36: L | E36: F | F36: red athletic dress | I36: Dresses | J36: Sell
A37: =IF(C37="","","T"&TEXT(B37,"000")&"I"&TEXT(COUNTIF(B$2:B37,B37),"000")) -> T003I003 | B37: 3 | C37: Old Navy | D37: S | E37: F | F37: cream crossbody bag | I37: Accessories | J37: Sell
A38: =IF(C38="","","T"&TEXT(B38,"000")&"I"&TEXT(COUNTIF(B$2:B38,B38),"000")) -> T003I004 | B38: 3 | C38: SO Clothing | D38: M | E38: F | F38: white wide leg pants | I38: Bottoms | J38: Sell
A39: =IF(C39="","","T"&TEXT(B39,"000")&"I"&TEXT(COUNTIF(B$2:B39,B39),"000")) -> T003I005 | B39: 3 | C39: H&M | D39: L | E39: F | F39: purple knit skirt | I39: Bottoms | J39: Keep
A40: =IF(C40="","","T"&TEXT(B40,"000")&"I"&TEXT(COUNTIF(B$2:B40,B40),"000")) -> T003I006 | B40: 3 | C40: Express | D40: S | E40: F | F40: tan cotton dress | I40: Dresses | J40: Keep
A41: =IF(C41="","","T"&TEXT(B41,"000")&"I"&TEXT(COUNTIF(B$2:B41,B41),"000")) -> T003I007 | B41: 3 | C41: Nike | D41: M | E41: F | F41: green leggings | I41: Bottoms | J41: Keep
A42: =IF(C42="","","T"&TEXT(B42,"000")&"I"&TEXT(COUNTIF(B$2:B42,B42),"000")) -> T003I008 | B42: 3 | C42: Other | D42: L | E42: F | F42: coral wide leg pants | I42: Bottoms | J42: Discard
A43: =IF(C43="","","T"&TEXT(B43,"000")&"I"&TEXT(COUNTIF(B$2:B43,B43),"000")) -> T003I009 | B43: 3 | C43: Free People | D43: M | E43: F | F43: olive cropped denim top | H43: heavy pilling | I43: Tops | J43: Discard
...

Sheet Listings
A1: Listing_ID | B1: SKU | C1: Listing_Date | D1: Original_Price | E1: Condition | F1: Condition Notes | G1: Package_Size | H1: Brand_Lookup | I1: Category_Lookup | J1: Match_Key
A2: =IF(B2="","",ROW()-1) -> 1 | B2: T001I002 | C2: 45939 | D2: 17 | E2: Used - Good | F2: minor fading | G2: M | H2: =IF(B2="","",VLOOKUP(B2,Items!A:I,3,FALSE)) -> Levi's | I2: =IF(B2="","",VLOOKUP(B2,Items!A:I,9,FALSE)) -> Jumpsuits/Rompers | J2: =IF(B2="","",TEXT(C2,"MM/DD/YYYY")&H2&I2) -> 10/09/2025Levi'sJumpsuits/Rompers
A3: =IF(B3="","",ROW()-1) -> 2 | B3: T001I008 | C3: 45939 | D3: 30 | E3: Like New | G3: S | H3: =IF(B3="","",VLOOKUP(B3,Items!A:I,3,FALSE)) -> Levi's | I3: =IF(B3="","",VLOOKUP(B3,Items!A:I,9,FALSE)) -> Footwear | J3: =IF(B3="","",TEXT(C3,"MM/DD/YYYY")&H3&I3) -> 10/09/2025Levi'sFootwear
A4: =IF(B4="","",ROW()-1) -> 3 | B4: T001I005 | C4: 45941 | D4: 29 | E4: Used - Good | G4: M | H4: =IF(B4="","",VLOOKUP(B4,Items!A:I,3,FALSE)) -> Deb | I4: =IF(B4="","",VLOOKUP(B4,Items!A:I,9,FALSE)) -> Bottoms | J4: =IF(B4="","",TEXT(C4,"MM/DD/YYYY")&H4&I4) -> 10/11/2025DebBottoms
A5: =IF(B5="","",ROW()-1) -> 4 | B5: T001I001 | C5: 45942 | D5: 20 | E5: Used - Good | G5: XS | H5: =IF(B5="","",VLOOKUP(B5,Items!A:I,3,FALSE)) -> J.Crew | I5: =IF(B5="","",VLOOKUP(B5,Items!A:I,9,FALSE)) -> Accessories | J5: =IF(B5="","",TEXT(C5,"MM/DD/YYYY")&H5&I5) -> 10/12/2025J.CrewAccessories
A6: =IF(B6="","",ROW()-1) -> 5 | B6: T001I010 | C6: 45943 | D6: 20 | E6: Used - Good | F6: minor fading | G6: S | H6: =IF(B6="","",VLOOKUP(B6,Items!A:I,3,FALSE)) -> H&M | I6: =IF(B6="","",VLOOKUP(B6,Items!A:I,9,FALSE)) -> Tops | J6: =IF(B6="","",TEXT(C6,"MM/DD/YYYY")&H6&I6) -> 10/13/2025H&MTops
A7: =IF(B7="","",ROW()-1) -> 6 | B7: T001I009 | C7: 45944 | D7: 18 | E7: Used - Good | F7: small mark on back | G7: M | H7: =IF(B7="","",VLOOKUP(B7,Items!A:I,3,FALSE)) -> Express | I7: =IF(B7="","",VLOOKUP(B7,Items!A:I,9,FALSE)) -> Bottoms | J7: =IF(B7="","",TEXT(C7,"MM/DD/YYYY")&H7&I7) -> 10/14/2025ExpressBottoms
A8: =IF(B8="","",ROW()-1) -> 7 | B8: T001I011 | C8: 45947 | D8: 14 | E8: Used - Excellent | F8: like new condition | G8: S | H8: =IF(B8="","",VLOOKUP(B8,Items!A:I,3,FALSE)) -> LOFT | I8: =IF(B8="","",VLOOKUP(B8,Items!A:I,9,FALSE)) -> Tops | J8: =IF(B8="","",TEXT(C8,"MM/DD/YYYY")&H8&I8) -> 10/17/2025LOFTTops
A9: =IF(B9="","",ROW()-1) -> 8 | B9: T001I007 | C9: 45949 | D9: 24 | E9: Used - Excellent | G9: XS | H9: =IF(B9="","",VLOOKUP(B9,Items!A:I,3,FALSE)) -> BKE | I9: =IF(B9="","",VLOOKUP(B9,Items!A:I,9,FALSE)) -> Tops | J9: =IF(B9="","",TEXT(C9,"MM/DD/YYYY")&H9&I9) -> 10/19/2025BKETops
A10: =IF(B10="","",ROW()-1) -> 9 | B10: T001I004 | C10: 45950 | D10: 23 | E10: Used - Excellent | G10: L | H10: =IF(B10="","",VLOOKUP(B10,Items!A:I,3,FALSE)) -> Patagonia | I10: =IF(B10="","",VLOOKUP(B10,Items!A:I,9,FALSE)) -> Dresses | J10: =IF(B10="","",TEXT(C10,"MM/DD/YYYY")&H10&I10) -> 10/20/2025PatagoniaDresses
A11: =IF(B11="","",ROW()-1) -> 10 | B11: T001I003 | C11: 45951 | D11: 14 | E11: Used - Excellent | F11: like new condition | G11: M | H11: =IF(B11="","",VLOOKUP(B11,Items!A:I,3,FALSE)) -> Zara | I11: =IF(B11="","",VLOOKUP(B11,Items!A:I,9,FALSE)) -> Bottoms | J11: =IF(B11="","",TEXT(C11,"MM/DD/YYYY")&H11&I11) -> 10/21/2025ZaraBottoms
A12: =IF(B12="","",ROW()-1) -> 11 | B12: T002I003 | C12: 45955 | D12: 13 | E12: Used - Excellent | G12: S | H12: =IF(B12="","",VLOOKUP(B12,Items!A:I,3,FALSE)) -> Other | I12: =IF(B12="","",VLOOKUP(B12,Items!A:I,9,FALSE)) -> Tops | J12: =IF(B12="","",TEXT(C12,"MM/DD/YYYY")&H12&I12) -> 10/25/2025OtherTops
A13: =IF(B13="","",ROW()-1) -> 12 | B13: T002I006 | C13: 45957 | D13: 8 | E13: Used - Good | G13: XXS | H13: =IF(B13="","",VLOOKUP(B13,Items!A:I,3,FALSE)) -> Nike | I13: =IF(B13="","",VLOOKUP(B13,Items!A:I,9,FALSE)) -> Accessories | J13: =IF(B13="","",TEXT(C13,"MM/DD/YYYY")&H13&I13) -> 10/27/2025NikeAccessories
A14: =IF(B14="","",ROW()-1) -> 13 | B14: T002I001 | C14: 45961 | D14: 40 | E14: Used - Excellent | G14: M | H14: =IF(B14="","",VLOOKUP(B14,Items!A:I,3,FALSE)) -> Gap | I14: =IF(B14="","",VLOOKUP(B14,Items!A:I,9,FALSE)) -> Dresses | J14: =IF(B14="","",TEXT(C14,"MM/DD/YYYY")&H14&I14) -> 10/31/2025GapDresses
A15: =IF(B15="","",ROW()-1) -> 14 | B15: T002I008 | C15: 45961 | D15: 25 | E15: Used - Good | F15: small mark on back | G15: S | H15: =IF(B15="","",VLOOKUP(B15,Items!A:I,3,FALSE)) -> J.Crew | I15: =IF(B15="","",VLOOKUP(B15,Items!A:I,9,FALSE)) -> Dresses | J15: =IF(B15="","",TEXT(C15,"MM/DD/YYYY")&H15&I15) -> 10/31/2025J.CrewDresses
A16: =IF(B16="","",ROW()-1) -> 15 | B16: T002I004 | C16: 45962 | D16: 28 | E16: Brand New | F16: tags still attached | G16: M | H16: =IF(B16="","",VLOOKUP(B16,Items!A:I,3,FALSE)) -> SO Clothing | I16: =IF(B16="","",VLOOKUP(B16,Items!A:I,9,FALSE)) -> Dresses | J16: =IF(B16="","",TEXT(C16,"MM/DD/YYYY")&H16&I16) -> 11/01/2025SO ClothingDresses
A17: =IF(B17="","",ROW()-1) -> 16 | B17: T002I009 | C17: 45962 | D17: 12 | E17: Like New | G17: M | H17: =IF(B17="","",VLOOKUP(B17,Items!A:I,3,FALSE)) -> Apt. 9 | I17: =IF(B17="","",VLOOKUP(B17,Items!A:I,9,FALSE)) -> Jumpsuits/Rompers | J17: =IF(B17="","",TEXT(C17,"MM/DD/YYYY")&H17&I17) -> 11/01/2025Apt. 9Jumpsuits/Rompers
A18: =IF(B18="","",ROW()-1) -> 17 | B18: T002I002 | C18: 45963 | D18: 5 | E18: Like New | G18: S | H18: =IF(B18="","",VLOOKUP(B18,Items!A:I,3,FALSE)) -> Adidas | I18: =IF(B18="","",VLOOKUP(B18,Items!A:I,9,FALSE)) -> Tops | J18: =IF(B18="","",TEXT(C18,"MM/DD/YYYY")&H18&I18) -> 11/02/2025AdidasTops
A19: =IF(B19="","",ROW()-1) -> 18 | B19: T002I010 | C19: 45965 | D19: 26 | E19: Like New | G19: M | H19: =IF(B19="","",VLOOKUP(B19,Items!A:I,3,FALSE)) -> Levi's | I19: =IF(B19="","",VLOOKUP(B19,Items!A:I,9,FALSE)) -> Dresses | J19: =IF(B19="","",TEXT(C19,"MM/DD/YYYY")&H19&I19) -> 11/04/2025Levi'sDresses
A20: =IF(B20="","",ROW()-1) -> 19 | B20: T002I005 | C20: 45966 | D20: 12 | E20: Used - Excellent | G20: M | H20: =IF(B20="","",VLOOKUP(B20,Items!A:I,3,FALSE)) -> Hollister | I20: =IF(B20="","",VLOOKUP(B20,Items!A:I,9,FALSE)) -> Footwear | J20: =IF(B20="","",TEXT(C20,"MM/DD/YYYY")&H20&I20) -> 11/05/2025HollisterFootwear
A21: =IF(B21="","",ROW()-1) -> 20 | B21: T002I007 | C21: 45966 | D21: 19 | E21: Used - Good | F21: minor fading | G21: S | H21: =IF(B21="","",VLOOKUP(B21,Items!A:I,3,FALSE)) -> Victoria's Secret | I21: =IF(B21="","",VLOOKUP(B21,Items!A:I,9,FALSE)) -> Tops | J21: =IF(B21="","",TEXT(C21,"MM/DD/YYYY")&H21&I21) -> 11/05/2025Victoria's SecretTops
A22: =IF(B22="","",ROW()-1) -> 21 | B22: T003I001 | C22: 45970 | D22: 20 | E22: Used - Excellent | F22: like new condition | G22: M | H22: =IF(B22="","",VLOOKUP(B22,Items!A:I,3,FALSE)) -> Free People | I22: =IF(B22="","",VLOOKUP(B22,Items!A:I,9,FALSE)) -> Tops | J22: =IF(B22="","",TEXT(C22,"MM/DD/YYYY")&H22&I22) -> 11/09/2025Free PeopleTops
A23: =IF(B23="","",ROW()-1) -> 22 | B23: T003I004 | C23: 45971 | D23: 22 | E23: Used - Good | F23: light wear | G23: S | H23: =IF(B23="","",VLOOKUP(B23,Items!A:I,3,FALSE)) -> SO Clothing | I23: =IF(B23="","",VLOOKUP(B23,Items!A:I,9,FALSE)) -> Bottoms | J23: =IF(B23="","",TEXT(C23,"MM/DD/YYYY")&H23&I23) -> 11/10/2025SO ClothingBottoms
A24: =IF(B24="","",ROW()-1) -> 23 | B24: T003I002 | C24: 45978 | D24: 35 | E24: Used - Good | F24: small mark on back | G24: S | H24: =IF(B24="","",VLOOKUP(B24,Items!A:I,3,FALSE)) -> Forever 21 | I24: =IF(B24="","",VLOOKUP(B24,Items!A:I,9,FALSE)) -> Dresses | J24: =IF(B24="","",TEXT(C24,"MM/DD/YYYY")&H24&I24) -> 11/17/2025Forever 21Dresses
A25: =IF(B25="","",ROW()-1) -> 24 | B25: T004I001 | C25: 45989 | D25: 32 | E25: Used - Excellent | G25: M | H25: =IF(B25="","",VLOOKUP(B25,Items!A:I,3,FALSE)) -> Other | I25: =IF(B25="","",VLOOKUP(B25,Items!A:I,9,FALSE)) -> Dresses | J25: =IF(B25="","",TEXT(C25,"MM/DD/YYYY")&H25&I25) -> 11/28/2025OtherDresses
A26: =IF(B26="","",ROW()-1) -> 25 | B26: T004I003 | C26: 45990 | D26: 30 | E26: Used - Excellent | F26: barely worn | G26: L | H26: =IF(B26="","",VLOOKUP(B26,Items!A:I,3,FALSE)) -> H&M | I26: =IF(B26="","",VLOOKUP(B26,Items!A:I,9,FALSE)) -> Dresses | J26: =IF(B26="","",TEXT(C26,"MM/DD/YYYY")&H26&I26) -> 11/29/2025H&MDresses
A27: =IF(B27="","",ROW()-1) -> 26 | B27: T004I004 | C27: 45991 | D27: 29 | E27: Used - Good | F27: light wear | G27: S | H27: =IF(B27="","",VLOOKUP(B27,Items!A:I,3,FALSE)) -> LOFT | I27: =IF(B27="","",VLOOKUP(B27,Items!A:I,9,FALSE)) -> Dresses | J27: =IF(B27="","",TEXT(C27,"MM/DD/YYYY")&H27&I27) -> 11/30/2025LOFTDresses
A28: =IF(B28="","",ROW()-1) -> 27 | B28: T004I002 | C28: 45992 | D28: 14 | E28: Brand New | G28: XS | H28: =IF(B28="","",VLOOKUP(B28,Items!A:I,3,FALSE)) -> Tommy Hilfiger | I28: =IF(B28="","",VLOOKUP(B28,Items!A:I,9,FALSE)) -> Tops | J28: =IF(B28="","",TEXT(C28,"MM/DD/YYYY")&H28&I28) -> 12/01/2025Tommy HilfigerTops
A29: =IF(B29="","",ROW()-1) -> 28 | B29: T005I002 | C29: 46004 | D29: 12 | E29: Used - Fair | F29: small snag near hem | G29: L | H29: =IF(B29="","",VLOOKUP(B29,Items!A:I,3,FALSE)) -> Patagonia | I29: =IF(B29="","",VLOOKUP(B29,Items!A:I,9,FALSE)) -> Footwear | J29: =IF(B29="","",TEXT(C29,"MM/DD/YYYY")&H29&I29) -> 12/13/2025PatagoniaFootwear
A30: =IF(B30="","",ROW()-1) -> 29 | B30: T005I003 | C30: 46009 | D30: 7 | E30: Used - Fair | F30: slight fading | G30: S | H30: =IF(B30="","",VLOOKUP(B30,Items!A:I,3,FALSE)) -> Express | I30: =IF(B30="","",VLOOKUP(B30,Items!A:I,9,FALSE)) -> Tops | J30: =IF(B30="","",TEXT(C30,"MM/DD/YYYY")&H30&I30) -> 12/18/2025ExpressTops
A31: =IF(B31="","",ROW()-1) -> 30 | B31: T006I007 | C31: 46012 | D31: 15 | E31: Used - Good | G31: XXS | H31: =IF(B31="","",VLOOKUP(B31,Items!A:I,3,FALSE)) -> Victoria's Secret | I31: =IF(B31="","",VLOOKUP(B31,Items!A:I,9,FALSE)) -> Swimwear | J31: =IF(B31="","",TEXT(C31,"MM/DD/YYYY")&H31&I31) -> 12/21/2025Victoria's SecretSwimwear
A32: =IF(B32="","",ROW()-1) -> 31 | B32: T006I001 | C32: 46012 | D32: 34 | E32: Used - Good | F32: small mark on back | G32: M | H32: =IF(B32="","",VLOOKUP(B32,Items!A:I,3,FALSE)) -> Adidas | I32: =IF(B32="","",VLOOKUP(B32,Items!A:I,9,FALSE)) -> Dresses | J32: =IF(B32="","",TEXT(C32,"MM/DD/YYYY")&H32&I32) -> 12/21/2025AdidasDresses
A33: =IF(B33="","",ROW()-1) -> 32 | B33: T006I011 | C33: 46012 | D33: 6 | E33: Used - Excellent | F33: barely worn | G33: S | H33: =IF(B33="","",VLOOKUP(B33,Items!A:I,3,FALSE)) -> Calvin Klein | I33: =IF(B33="","",VLOOKUP(B33,Items!A:I,9,FALSE)) -> Tops | J33: =IF(B33="","",TEXT(C33,"MM/DD/YYYY")&H33&I33) -> 12/21/2025Calvin KleinTops
A34: =IF(B34="","",ROW()-1) -> 33 | B34: T006I010 | C34: 46013 | D34: 26 | E34: Used - Good | G34: S | H34: =IF(B34="","",VLOOKUP(B34,Items!A:I,3,FALSE)) -> Aerie | I34: =IF(B34="","",VLOOKUP(B34,Items!A:I,9,FALSE)) -> Footwear | J34: =IF(B34="","",TEXT(C34,"MM/DD/YYYY")&H34&I34) -> 12/22/2025AerieFootwear
A35: =IF(B35="","",ROW()-1) -> 34 | B35: T005I001 | C35: 46015 | D35: 8 | E35: Used - Excellent | F35: like new condition | G35: XS | H35: =IF(B35="","",VLOOKUP(B35,Items!A:I,3,FALSE)) -> H&M | I35: =IF(B35="","",VLOOKUP(B35,Items!A:I,9,FALSE)) -> Swimwear | J35: =IF(B35="","",TEXT(C35,"MM/DD/YYYY")&H35&I35) -> 12/24/2025H&MSwimwear
A36: =IF(B36="","",ROW()-1) -> 35 | B36: T006I008 | C36: 46016 | D36: 18 | E36: Used - Excellent | G36: L | H36: =IF(B36="","",VLOOKUP(B36,Items!A:I,3,FALSE)) -> SO Clothing | I36: =IF(B36="","",VLOOKUP(B36,Items!A:I,9,FALSE)) -> Coats/Jackets | J36: =IF(B36="","",TEXT(C36,"MM/DD/YYYY")&H36&I36) -> 12/25/2025SO ClothingCoats/Jackets
A37: =IF(B37="","",ROW()-1) -> 36 | B37: T006I005 | C37: 46017 | D37: 16 | E37: Used - Good | G37: S | H37: =IF(B37="","",VLOOKUP(B37,Items!A:I,3,FALSE)) -> Free People | I37: =IF(B37="","",VLOOKUP(B37,Items!A:I,9,FALSE)) -> Bottoms | J37: =IF(B37="","",TEXT(C37,"MM/DD/YYYY")&H37&I37) -> 12/26/2025Free PeopleBottoms
A38: =IF(B38="","",ROW()-1) -> 37 | B38: T006I003 | C38: 46019 | D38: 21 | E38: Used - Excellent | F38: like new condition | G38: XS | H38: =IF(B38="","",VLOOKUP(B38,Items!A:I,3,FALSE)) -> BKE | I38: =IF(B38="","",VLOOKUP(B38,Items!A:I,9,FALSE)) -> Tops | J38: =IF(B38="","",TEXT(C38,"MM/DD/YYYY")&H38&I38) -> 12/28/2025BKETops
A39: =IF(B39="","",ROW()-1) -> 38 | B39: T006I002 | C39: 46020 | D39: 9 | E39: Used - Fair | F39: slight fading | G39: XS | H39: =IF(B39="","",VLOOKUP(B39,Items!A:I,3,FALSE)) -> American Eagle | I39: =IF(B39="","",VLOOKUP(B39,Items!A:I,9,FALSE)) -> Swimwear | J39: =IF(B39="","",TEXT(C39,"MM/DD/YYYY")&H39&I39) -> 12/29/2025American EagleSwimwear
A40: =IF(B40="","",ROW()-1) -> 39 | B40: T007I001 | C40: 46022 | D40: 20 | E40: Like New | G40: XS | H40: =IF(B40="","",VLOOKUP(B40,Items!A:I,3,FALSE)) -> Hollister | I40: =IF(B40="","",VLOOKUP(B40,Items!A:I,9,FALSE)) -> Tops | J40: =IF(B40="","",TEXT(C40,"MM/DD/YYYY")&H40&I40) -> 12/31/2025HollisterTops
...

Sheet Sales
A1: Date of sale | B1: Time of sale | C1: Date of listing | D1: Bundle | E1: Bundle - amount of items | F1: Buyer | G1: Brand | H1: Description | I1: Size | J1: Item price | K1: Buyer shipping cost | L1: Total | M1: USPS Cost | N1: Depop fee | O1: Depop Payments fee | P1: Buyer Marketplace Fee | Q1: Boosting fee | R1: Payment type | S1: Estimated payout date | T1: Payout arrival date | U1: Category | V1: Name | W1: Address Line 1 | X1: Address Line 2 | Y1: City | Z1: State | AA1: Post Code | AB1: Country | AC1: US Sales tax | AD1: Refunded to buyer amount | AE1: Fees refunded to seller | AF1: Days_to_Sell | AG1: Alloc_Shipping | AH1: Alloc_Fees | AI1: Listing_ID
A2: 45946 | B2: 02:15 PM | C2: 45944 | D2: No | F2: kayla62 | G2: Express | H2: Express red vintage jeans in size m #minimalist #streetwear #y2k #thrift | I2: M | J2: 18 | K2: 7.99 | L2: 27.79 | M2: 0 | N2: 0 | O2: 1.42 | P2: 1.8 | R2: STRIPE | S2: 45948 | T2: 45950 | U2: Bottoms | V2: Colleen Nguyen | W2: 05641 Robin Port | Y2: Jasonfort | Z2: CO | AA2: 52357 | AB2: US | AF2: =IF(OR(A2="",C2=""),"",A2-C2) -> 2 | AG2: =IF(A2="","",IF(D2="No",IFERROR(K2*1,0),IF(D2="Yes",IFERROR(K2/E2,0),""))) -> 7.99 | AH2: =IF(A2="","",IFERROR(N2*1,0)+IFERROR(O2*1,0)+IFERROR(P2*1,0)+IFERROR(Q2*1,0)) -> 3.22 | AI2: {=IF(A2="","",IFERROR(INDEX(Listings!A:A,MATCH(TEXT(C2,"MM/DD/YYYY")&G2&U2,Listings!J$2:J$201,0)+1),""))} -> 6
A3: 45948 | B3: 06:35 PM | C3: 45942 | D3: No | F3: david_nielsen | G3: J.Crew | H3: J.Crew navy sunglasses in size s/m #aesthetic #grunge #thrift #boho #vintage | I3: S/M | J3: 15 | K3: 11.99 | L3: 28.49 | M3: 0 | N3: 0 | O3: 1.19 | P3: 1.5 | R3: STRIPE | S3: 45950 | T3: 45953 | U3: Accessories | V3: Andrew Stevens | W3: 495 Janet Cape | Y3: Port Keith | Z3: MI | AA3: 10959 | AB3: US | AF3: =IF(OR(A3="",C3=""),"",A3-C3) -> 6 | AG3: =IF(A3="","",IF(D3="No",IFERROR(K3*1,0),IF(D3="Yes",IFERROR(K3/E3,0),""))) -> 11.99 | AH3: =IF(A3="","",IFERROR(N3*1,0)+IFERROR(O3*1,0)+IFERROR(P3*1,0)+IFERROR(Q3*1,0)) -> 2.69 | AI3: {=IF(A3="","",IFERROR(INDEX(Listings!A:A,MATCH(TEXT(C3,"MM/DD/YYYY")&G3&U3,Listings!J$2:J$201,0)+1),""))} -> 4
A4: 45948 | B4: 09:22 AM | C4: 45943 | D4: No | F4: shawn_flowers | G4: H&M | H4: H&M striped denim tank top in size l #retro #minimalist #boho #thrift | I4: L | J4: 15 | K4: 11.99 | L4: 28.49 | M4: 0 | N4: 0 | O4: 1.19 | P4: 1.5 | R4: STRIPE | S4: 45950 | T4: 45953 | U4: Tops | V4: Sharon James | W4: 5341 Amanda Gardens | Y4: South Noah | Z4: AL | AA4: 84387 | AB4: US | AC4: 0.78 | AF4: =IF(OR(A4="",C4=""),"",A4-C4) -> 5 | AG4: =IF(A4="","",IF(D4="No",IFERROR(K4*1,0),IF(D4="Yes",IFERROR(K4/E4,0),""))) -> 11.99 | AH4: =IF(A4="","",IFERROR(N4*1,0)+IFERROR(O4*1,0)+IFERROR(P4*1,0)+IFERROR(Q4*1,0)) -> 2.69 | AI4: {=IF(A4="","",IFERROR(INDEX(Listings!A:A,MATCH(TEXT(C4,"MM/DD/YYYY")&G4&U4,Listings!J$2:J$201,0)+1),""))} -> 5
A5: 45950 | B5: 12:26 PM | C5: 45949 | D5: No | F5: styledonald | G5: BKE | H5: BKE striped boho tank top in size s #cottagecore #vintage #y2k #casual | I5: S | J5: 21.6 | K5: 6.49 | L5: 30.25 | M5: 0 | N5: 0 | O5: 1.71 | P5: 2.16 | R5: STRIPE | S5: 45952 | T5: 45955 | U5: Tops | V5: Maria Thomas | W5: 969 Cox Dam Suite 101 | Y5: Lake Ernest | Z5: CO | AA5: 89693 | AB5: US | AF5: =IF(OR(A5="",C5=""),"",A5-C5) -> 1 | AG5: =IF(A5="","",IF(D5="No",IFERROR(K5*1,0),IF(D5="Yes",IFERROR(K5/E5,0),""))) -> 6.49 | AH5: =IF(A5="","",IFERROR(N5*1,0)+IFERROR(O5*1,0)+IFERROR(P5*1,0)+IFERROR(Q5*1,0)) -> 3.87 | AI5: {=IF(A5="","",IFERROR(INDEX(Listings!A:A,MATCH(TEXT(C5,"MM/DD/YYYY")&G5&U5,Listings!J$2:J$201,0)+1),""))} -> 8
A6: 45952 | B6: 03:39 PM | C6: 45941 | D6: No | F6: stylerobert | G6: Deb | H6: Deb plaid cotton jeans in size s #minimalist #preppy #streetwear | I6: S | J6: 29 | K6: 4.99 | L6: 36.89 | M6: 0 | N6: 0 | O6: 2.29 | P6: 2.9 | R6: STRIPE | S6: 45954 | T6: 45957 | U6: Bottoms | V6: Michelle Miles | W6: 402 Peterson Drives Apt. 511 | Y6: Davisstad | Z6: MO | AA6: 79632 | AB6: US | AF6: =IF(OR(A6="",C6=""),"",A6-C6) -> 11 | AG6: =IF(A6="","",IF(D6="No",IFERROR(K6*1,0),IF(D6="Yes",IFERROR(K6/E6,0),""))) -> 4.99 | AH6: =IF(A6="","",IFERROR(N6*1,0)+IFERROR(O6*1,0)+IFERROR(P6*1,0)+IFERROR(Q6*1,0)) -> 5.19 | AI6: {=IF(A6="","",IFERROR(INDEX(Listings!A:A,MATCH(TEXT(C6,"MM/DD/YYYY")&G6&U6,Listings!J$2:J$201,0)+1),""))} -> 3
A7: 45955 | B7: 08:58 AM | C7: 45951 | D7: No | F7: wendystyle | G7: Zara | H7: Zara green joggers in size s #minimalist #boho #vintage | I7: S | J7: 10.5 | K7: 6.49 | L7: 18.04 | M7: 0 | N7: 0 | O7: 0.83 | P7: 1.05 | R7: STRIPE | S7: 45957 | T7: 45959 | U7: Bottoms | V7: Arthur James | W7: 018 Mack Junctions Apt. 462 | Y7: Smithview | Z7: IA | AA7: 66113 | AB7: US | AC7: 1.05 | AF7: =IF(OR(A7="",C7=""),"",A7-C7) -> 4 | AG7: =IF(A7="","",IF(D7="No",IFERROR(K7*1,0),IF(D7="Yes",IFERROR(K7/E7,0),""))) -> 6.49 | AH7: =IF(A7="","",IFERROR(N7*1,0)+IFERROR(O7*1,0)+IFERROR(P7*1,0)+IFERROR(Q7*1,0)) -> 1.88 | AI7: {=IF(A7="","",IFERROR(INDEX(Listings!A:A,MATCH(TEXT(C7,"MM/DD/YYYY")&G7&U7,Listings!J$2:J$201,0)+1),""))} -> 10
A8: 45956 | B8: 10:59 AM | C8: 45955 | D8: No | F8: colleenski | G8: Other | H8: Other black denim blouse in size s #boho #sustainable #y2k #grunge #thrift | I8: S | J8: 9.1 | K8: 5.99 | L8: 16 | M8: 0 | N8: 0 | O8: 0.72 | P8: 0.91 | R8: STRIPE | S8: 45958 | T8: 45961 | U8: Tops | V8: Katie Rodriguez | W8: 52880 Burns Creek | Y8: Natashaport | Z8: CO | AA8: 31886 | AB8: US | AC8: 0.63 | AF8: =IF(OR(A8="",C8=""),"",A8-C8) -> 1 | AG8: =IF(A8="","",IF(D8="No",IFERROR(K8*1,0),IF(D8="Yes",IFERROR(K8/E8,0),""))) -> 5.99 | AH8: =IF(A8="","",IFERROR(N8*1,0)+IFERROR(O8*1,0)+IFERROR(P8*1,0)+IFERROR(Q8*1,0)) -> 1.63 | AI8: {=IF(A8="","",IFERROR(INDEX(Listings!A:A,MATCH(TEXT(C8,"MM/DD/YYYY")&G8&U8,Listings!J$2:J$201,0)+1),""))} -> 11
A9: 45963 | B9: 08:45 AM | C9: 45939 | D9: No | F9: jeffreyfinds | G9: Levi's | H9: Levi's green flats in size 10 #streetwear #retro #grunge | I9: 10 | J9: 30 | K9: 4.99 | L9: 37.99 | M9: 0 | N9: 0 | O9: 2.37 | P9: 3 | R9: STRIPE | S9: 45965 | T9: 45969 | U9: Footwear | V9: Allison Hill | W9: 819 Johnson Course | Y9: East William | Z9: NJ | AA9: 03979 | AB9: US | AC9: 2.06 | AF9: =IF(OR(A9="",C9=""),"",A9-C9) -> 24 | AG9: =IF(A9="","",IF(D9="No",IFERROR(K9*1,0),IF(D9="Yes",IFERROR(K9/E9,0),""))) -> 4.99 | AH9: =IF(A9="","",IFERROR(N9*1,0)+IFERROR(O9*1,0)+IFERROR(P9*1,0)+IFERROR(Q9*1,0)) -> 5.37 | AI9: {=IF(A9="","",IFERROR(INDEX(Listings!A:A,MATCH(TEXT(C9,"MM/DD/YYYY")&G9&U9,Listings!J$2:J$201,0)+1),""))} -> 2
A10: 45966 | B10: 03:21 PM | C10: 45962 | D10: No | F10: vintagejohn | G10: SO Clothing | H10: SO Clothing brown bodycon dress in size xs #cottagecore #y2k | I10: XS | J10: 28 | K10: 11.99 | L10: 42.79 | M10: 0 | N10: 0 | O10: 2.21 | P10: 2.8 | R10: STRIPE | S10: 45968 | T10: 45972 | U10: Dresses | V10: Shannon Jones | W10: 82997 Kristen Valley Suite 311 | Y10: Gomezchester | Z10: CA | AA10: 61714 | AB10: US | AF10: =IF(OR(A10="",C10=""),"",A10-C10) -> 4 | AG10: =IF(A10="","",IF(D10="No",IFERROR(K10*1,0),IF(D10="Yes",IFERROR(K10/E10,0),""))) -> 11.99 | AH10: =IF(A10="","",IFERROR(N10*1,0)+IFERROR(O10*1,0)+IFERROR(P10*1,0)+IFERROR(Q10*1,0)) -> 5.01 | AI10: {=IF(A10="","",IFERROR(INDEX(Listings!A:A,MATCH(TEXT(C10,"MM/DD/YYYY")&G10&U10,Listings!J$2:J$201,0)+1),""))} -> 15
A11: 45966 | B11: 06:26 PM | C11: 45963 | D11: No | F11: melissagar | G11: Adidas | H11: Adidas coral long sleeve boho shirt in size l #retro #streetwear | I11: L | J11: 4.5 | K11: 6.49 | L11: 11.44 | M11: 0 | N11: 0 | O11: 0.36 | P11: 0.45 | R11: STRIPE | S11: 45968 | T11: 45972 | U11: Tops | V11: Angela Morton | W11: 32677 Michelle Circle | Y11: South Aaron | Z11: KY | AA11: 51674 | AB11: US | AC11: 0.24 | AF11: =IF(OR(A11="",C11=""),"",A11-C11) -> 3 | AG11: =IF(A11="","",IF(D11="No",IFERROR(K11*1,0),IF(D11="Yes",IFERROR(K11/E11,0),""))) -> 6.49 | AH11: =IF(A11="","",IFERROR(N11*1,0)+IFERROR(O11*1,0)+IFERROR(P11*1,0)+IFERROR(Q11*1,0)) -> 0.81 | AI11: {=IF(A11="","",IFERROR(INDEX(Listings!A:A,MATCH(TEXT(C11,"MM/DD/YYYY")&G11&U11,Listings!J$2:J$201,0)+1),""))} -> 17
A12: 45971 | B12: 12:25 PM | C12: 45962 | D12: No | F12: styledebbie | G12: Apt. 9 | H12: Apt. 9 brown boho romper in size xs #sustainable #thrift #streetwear | I12: XS | J12: 10.8 | K12: 11.99 | L12: 23.87 | M12: 0 | N12: 0 | O12: 0.85 | P12: 1.08 | R12: STRIPE | S12: 45973 | T12: 45976 | U12: Jumpsuits/Rompers | V12: Amy Valdez | W12: 5133 Amanda Dam | Y12: Whitemouth | Z12: SC | AA12: 33243 | AB12: US | AF12: =IF(OR(A12="",C12=""),"",A12-C12) -> 9 | AG12: =IF(A12="","",IF(D12="No",IFERROR(K12*1,0),IF(D12="Yes",IFERROR(K12/E12,0),""))) -> 11.99 | AH12: =IF(A12="","",IFERROR(N12*1,0)+IFERROR(O12*1,0)+IFERROR(P12*1,0)+IFERROR(Q12*1,0)) -> 1.93 | AI12: {=IF(A12="","",IFERROR(INDEX(Listings!A:A,MATCH(TEXT(C12,"MM/DD/YYYY")&G12&U12,Listings!J$2:J$201,0)+1),""))} -> 16
A13: 45975 | B13: 06:04 PM | C13: 45965 | D13: No | F13: rodney_bernard | G13: Levi's | H13: Levi's pink cotton dress in size m #thrift #grunge #retro | I13: M | J13: 19.5 | K13: 3.99 | L13: 25.44 | M13: 0 | N13: 0 | O13: 1.54 | P13: 1.95 | R13: STRIPE | S13: 45977 | T13: 45979 | U13: Dresses | V13: Richard Gibson | W13: 34309 Julie Centers Apt. 978 | Y13: North Susan | Z13: OR | AA13: 11001 | AB13: US | AC13: 1.37 | AF13: =IF(OR(A13="",C13=""),"",A13-C13) -> 10 | AG13: =IF(A13="","",IF(D13="No",IFERROR(K13*1,0),IF(D13="Yes",IFERROR(K13/E13,0),""))) -> 3.99 | AH13: =IF(A13="","",IFERROR(N13*1,0)+IFERROR(O13*1,0)+IFERROR(P13*1,0)+IFERROR(Q13*1,0)) -> 3.49 | AI13: {=IF(A13="","",IFERROR(INDEX(Listings!A:A,MATCH(TEXT(C13,"MM/DD/YYYY")&G13&U13,Listings!J$2:J$201,0)+1),""))} -> 18
A14: 45975 | B14: 01:45 PM | C14: 45966 | D14: No | F14: michelle_powell | G14: Victoria's Secret | H14: Victoria's Secret green oversized cami in size m #streetwear #casual #vintage #retro #preppy | I14: M | J14: 19 | K14: 3.99 | L14: 24.89 | M14: 0 | N14: 0 | O14: 1.5 | P14: 1.9 | R14: STRIPE | S14: 45977 | T14: 45981 | U14: Tops | V14: Andrea Jones | W14: 909 Robert Prairie | Y14: Sarahborough | Z14: MA | AA14: 88283 | AB14: US | AC14: 1.28 | AF14: =IF(OR(A14="",C14=""),"",A14-C14) -> 9 | AG14: =IF(A14="","",IF(D14="No",IFERROR(K14*1,0),IF(D14="Yes",IFERROR(K14/E14,0),""))) -> 3.99 | AH14: =IF(A14="","",IFERROR(N14*1,0)+IFERROR(O14*1,0)+IFERROR(P14*1,0)+IFERROR(Q14*1,0)) -> 3.4 | AI14: {=IF(A14="","",IFERROR(INDEX(Listings!A:A,MATCH(TEXT(C14,"MM/DD/YYYY")&G14&U14,Listings!J$2:J$201,0)+1),""))} -> 20
A15: 45977 | B15: 03:45 PM | C15: 45961 | D15: No | F15: christophertuc | G15: Gap | H15: Gap plaid bodycon dress in size m #casual #cottagecore #aesthetic | I15: M | J15: 40 | K15: 11.99 | L15: 55.99 | M15: 0 | N15: 0 | O15: 3.16 | P15: 4 | R15: STRIPE | S15: 45979 | T15: 45982 | U15: Dresses | V15: Shawn Arroyo | W15: 227 Joseph Well | Y15: Brandtside | Z15: KY | AA15: 99495 | AB15: US | AF15: =IF(OR(A15="",C15=""),"",A15-C15) -> 16 | AG15: =IF(A15="","",IF(D15="No",IFERROR(K15*1,0),IF(D15="Yes",IFERROR(K15/E15,0),""))) -> 11.99 | AH15: =IF(A15="","",IFERROR(N15*1,0)+IFERROR(O15*1,0)+IFERROR(P15*1,0)+IFERROR(Q15*1,0)) -> 7.16 | AI15: {=IF(A15="","",IFERROR(INDEX(Listings!A:A,MATCH(TEXT(C15,"MM/DD/YYYY")&G15&U15,Listings!J$2:J$201,0)+1),""))} -> 13
A16: 45980 | B16: 11:20 PM | C16: 45961 | D16: No | F16: wandasan | G16: J.Crew | H16: J.Crew white mini dress in size l #boho #aesthetic | I16: L | J16: 25 | K16: 11.99 | L16: 39.49 | M16: 0 | N16: 0 | O16: 1.98 | P16: 2.5 | R16: STRIPE | S16: 45982 | T16: 45984 | U16: Dresses | V16: Christina Collins | W16: 713 Caleb Brooks Apt. 930 | Y16: Lake Crystalbury | Z16: PA | AA16: 09335 | AB16: US | AC16: 1.72 | AF16: =IF(OR(A16="",C16=""),"",A16-C16) -> 19 | AG16: =IF(A16="","",IF(D16="No",IFERROR(K16*1,0),IF(D16="Yes",IFERROR(K16/E16,0),""))) -> 11.99 | AH16: =IF(A16="","",IFERROR(N16*1,0)+IFERROR(O16*1,0)+IFERROR(P16*1,0)+IFERROR(Q16*1,0)) -> 4.48 | AI16: {=IF(A16="","",IFERROR(INDEX(Listings!A:A,MATCH(TEXT(C16,"MM/DD/YYYY")&G16&U16,Listings!J$2:J$201,0)+1),""))} -> 14
A17: 45984 | B17: 04:46 PM | C17: 45970 | D17: No | F17: emily15 | G17: Free People | H17: Free People purple long sleeve fitted shirt in size s #grunge #minimalist #y2k #retro #vintage | I17: S | J17: 20 | K17: 5.99 | L17: 27.99 | M17: 0 | N17: 0 | O17: 1.58 | P17: 2 | R17: STRIPE | S17: 45986 | T17: 45988 | U17: Tops | V17: Cynthia Foster | W17: 5107 Charles Forest Suite 251 | Y17: West Justin | Z17: AL | AA17: 57934 | AB17: US | AF17: =IF(OR(A17="",C17=""),"",A17-C17) -> 14 | AG17: =IF(A17="","",IF(D17="No",IFERROR(K17*1,0),IF(D17="Yes",IFERROR(K17/E17,0),""))) -> 5.99 | AH17: =IF(A17="","",IFERROR(N17*1,0)+IFERROR(O17*1,0)+IFERROR(P17*1,0)+IFERROR(Q17*1,0)) -> 3.58 | AI17: {=IF(A17="","",IFERROR(INDEX(Listings!A:A,MATCH(TEXT(C17,"MM/DD/YYYY")&G17&U17,Listings!J$2:J$201,0)+1),""))} -> 21
A18: 45993 | B18: 06:07 PM | C18: 45990 | D18: No | F18: josephfre | G18: H&M | H18: H&M coral sundress in size s #preppy #vintage | I18: S | J18: 30 | K18: 7.99 | L18: 40.99 | M18: 0 | N18: 0 | O18: 2.37 | P18: 3 | R18: STRIPE | S18: 45995 | T18: 45998 | U18: Dresses | V18: Christina Walters | W18: 64005 Dana Greens | Y18: Lake Scott | Z18: IN | AA18: 92994 | AB18: US | AF18: =IF(OR(A18="",C18=""),"",A18-C18) -> 3 | AG18: =IF(A18="","",IF(D18="No",IFERROR(K18*1,0),IF(D18="Yes",IFERROR(K18/E18,0),""))) -> 7.99 | AH18: =IF(A18="","",IFERROR(N18*1,0)+IFERROR(O18*1,0)+IFERROR(P18*1,0)+IFERROR(Q18*1,0)) -> 5.37 | AI18: {=IF(A18="","",IFERROR(INDEX(Listings!A:A,MATCH(TEXT(C18,"MM/DD/YYYY")&G18&U18,Listings!J$2:J$201,0)+1),""))} -> 25
A19: 45996 | B19: 09:59 AM | C19: 45971 | D19: No | F19: vanessafinds | G19: SO Clothing | H19: SO Clothing white wide leg pants in size m #streetwear #aesthetic #minimalist #y2k #retro | I19: M | J19: 22 | K19: 5.99 | L19: 30.19 | M19: 0 | N19: 0 | O19: 1.74 | P19: 2.2 | R19: STRIPE | S19: 45998 | T19: 46001 | U19: Bottoms | V19: Michele Carr | W19: 841 Joseph Coves | Y19: West Juan | Z19: PA | AA19: 28108 | AB19: US | AC19: 1.89 | AF19: =IF(OR(A19="",C19=""),"",A19-C19) -> 25 | AG19: =IF(A19="","",IF(D19="No",IFERROR(K19*1,0),IF(D19="Yes",IFERROR(K19/E19,0),""))) -> 5.99 | AH19: =IF(A19="","",IFERROR(N19*1,0)+IFERROR(O19*1,0)+IFERROR(P19*1,0)+IFERROR(Q19*1,0)) -> 3.94 | AI19: {=IF(A19="","",IFERROR(INDEX(Listings!A:A,MATCH(TEXT(C19,"MM/DD/YYYY")&G19&U19,Listings!J$2:J$201,0)+1),""))} -> 22
A20: 46024 | B20: 05:15 PM | C20: 46012 | D20: No | F20: stylegregory | G20: Victoria's Secret | H20: Victoria's Secret blue one-piece swimsuit in size m #retro #casual | I20: M | J20: 15 | K20: 4.99 | L20: 21.49 | M20: 0 | N20: 0 | O20: 1.19 | P20: 1.5 | R20: STRIPE | S20: 46026 | T20: 46030 | U20: Swimwear | V20: Ashley Waller | W20: 19655 Obrien Pass Apt. 693 | Y20: Bradleychester | Z20: IN | AA20: 00722 | AB20: US | AF20: =IF(OR(A20="",C20=""),"",A20-C20) -> 12 | AG20: =IF(A20="","",IF(D20="No",IFERROR(K20*1,0),IF(D20="Yes",IFERROR(K20/E20,0),""))) -> 4.99 | AH20: =IF(A20="","",IFERROR(N20*1,0)+IFERROR(O20*1,0)+IFERROR(P20*1,0)+IFERROR(Q20*1,0)) -> 2.69 | AI20: {=IF(A20="","",IFERROR(INDEX(Listings!A:A,MATCH(TEXT(C20,"MM/DD/YYYY")&G20&U20,Listings!J$2:J$201,0)+1),""))} -> 30
A21: 46025 | B21: 12:48 PM | C21: 46019 | D21: No | F21: robertshop | G21: BKE | H21: BKE cream lace sweater in size s #aesthetic #retro #minimalist #thrift #preppy | I21: S | J21: 21 | K21: 4.99 | L21: 28.09 | M21: 0 | N21: 0 | O21: 1.66 | P21: 2.1 | R21: STRIPE | S21: 46027 | T21: 46029 | U21: Tops | V21: Edward Martinez | W21: 299 Sullivan Village Apt. 443 | Y21: Floydmouth | Z21: MI | AA21: 61447 | AB21: US | AC21: 1.02 | AF21: =IF(OR(A21="",C21=""),"",A21-C21) -> 6 | AG21: =IF(A21="","",IF(D21="No",IFERROR(K21*1,0),IF(D21="Yes",IFERROR(K21/E21,0),""))) -> 4.99 | AH21: =IF(A21="","",IFERROR(N21*1,0)+IFERROR(O21*1,0)+IFERROR(P21*1,0)+IFERROR(Q21*1,0)) -> 3.76 | AI21: {=IF(A21="","",IFERROR(INDEX(Listings!A:A,MATCH(TEXT(C21,"MM/DD/YYYY")&G21&U21,Listings!J$2:J$201,0)+1),""))} -> 37
A22: 46025 | B22: 01:21 PM | C22: 46020 | D22: No | F22: laura44 | G22: American Eagle | H22: American Eagle teal boho bikini top in size m #cottagecore #casual #minimalist #vintage #y2k | I22: M | J22: 9 | K22: 6.49 | L22: 16.39 | M22: 0 | N22: 0 | O22: 0.71 | P22: 0.9 | R22: STRIPE | S22: 46027 | T22: 46030 | U22: Swimwear | V22: Michael Dixon | W22: 148 Davis Terrace | Y22: Lake Lance | Z22: NY | AA22: 26601 | AB22: US | AC22: 0.81 | AF22: =IF(OR(A22="",C22=""),"",A22-C22) -> 5 | AG22: =IF(A22="","",IF(D22="No",IFERROR(K22*1,0),IF(D22="Yes",IFERROR(K22/E22,0),""))) -> 6.49 | AH22: =IF(A22="","",IFERROR(N22*1,0)+IFERROR(O22*1,0)+IFERROR(P22*1,0)+IFERROR(Q22*1,0)) -> 1.61 | AI22: {=IF(A22="","",IFERROR(INDEX(Listings!A:A,MATCH(TEXT(C22,"MM/DD/YYYY")&G22&U22,Listings!J$2:J$201,0)+1),""))} -> 38
A23: 46026 | B23: 08:15 AM | C23: 46012 | D23: No | F23: lisa27 | G23: Adidas | H23: Adidas pink sundress in size m #sustainable #minimalist #casual #grunge | I23: M | J23: 28.9 | K23: 6.49 | L23: 38.28 | M23: 0 | N23: 0 | O23: 2.28 | P23: 2.89 | R23: STRIPE | S23: 46028 | T23: 46031 | U23: Dresses | V23: Shannon Walker | W23: 4330 Raymond Harbors Apt. 458 | Y23: Frazierside | Z23: GA | AA23: 43905 | AB23: US | AC23: 2.46 | AF23: =IF(OR(A23="",C23=""),"",A23-C23) -> 14 | AG23: =IF(A23="","",IF(D23="No",IFERROR(K23*1,0),IF(D23="Yes",IFERROR(K23/E23,0),""))) -> 6.49 | AH23: =IF(A23="","",IFERROR(N23*1,0)+IFERROR(O23*1,0)+IFERROR(P23*1,0)+IFERROR(Q23*1,0)) -> 5.17 | AI23: {=IF(A23="","",IFERROR(INDEX(Listings!A:A,MATCH(TEXT(C23,"MM/DD/YYYY")&G23&U23,Listings!J$2:J$201,0)+1),""))} -> 31
A24: 46026 | B24: 01:30 PM | C24: 46022 | D24: No | F24: cherylmac | G24: Hollister | H24: Hollister burgundy fitted tank top in size l #minimalist #streetwear | I24: L | J24: 20 | K24: 5.99 | L24: 27.99 | M24: 0 | N24: 0 | O24: 1.58 | P24: 2 | R24: STRIPE | S24: 46028 | T24: 46031 | U24: Tops | V24: Angel Riggs | W24: 9367 Sanchez Shoal Apt. 163 | Y24: Port Susan | Z24: IA | AA24: 68390 | AB24: US | AD24: 27.99 | AE24: 3.58 | AF24: =IF(OR(A24="",C24=""),"",A24-C24) -> 4 | AG24: =IF(A24="","",IF(D24="No",IFERROR(K24*1,0),IF(D24="Yes",IFERROR(K24/E24,0),""))) -> 5.99 | AH24: =IF(A24="","",IFERROR(N24*1,0)+IFERROR(O24*1,0)+IFERROR(P24*1,0)+IFERROR(Q24*1,0)) -> 3.58 | AI24: {=IF(A24="","",IFERROR(INDEX(Listings!A:A,MATCH(TEXT(C24,"MM/DD/YYYY")&G24&U24,Listings!J$2:J$201,0)+1),""))} -> 39
A25: 46027 | B25: 09:43 PM | C25: 45992 | D25: No | F25: vintagenicole | G25: Tommy Hilfiger | H25: Tommy Hilfiger navy denim cami in size xs #sustainable #minimalist #y2k #vintage | I25: XS | J25: 12.6 | K25: 6.49 | L25: 20.35 | M25: 0 | N25: 0 | O25: 1 | P25: 1.26 | R25: STRIPE | S25: 46029 | T25: 46033 | U25: Tops | V25: Adam Jones | W25: 059 Russell Canyon | Y25: Michaelton | Z25: WA | AA25: 47399 | AB25: US | AC25: 0.69 | AF25: =IF(OR(A25="",C25=""),"",A25-C25) -> 35 | AG25: =IF(A25="","",IF(D25="No",IFERROR(K25*1,0),IF(D25="Yes",IFERROR(K25/E25,0),""))) -> 6.49 | AH25: =IF(A25="","",IFERROR(N25*1,0)+IFERROR(O25*1,0)+IFERROR(P25*1,0)+IFERROR(Q25*1,0)) -> 2.26 | AI25: {=IF(A25="","",IFERROR(INDEX(Listings!A:A,MATCH(TEXT(C25,"MM/DD/YYYY")&G25&U25,Listings!J$2:J$201,0)+1),""))} -> 27
A26: 46028 | B26: 08:39 PM | C26: 46009 | D26: No | F26: kimberly_henson | G26: Express | H26: Express navy button-down shirt in size s #streetwear #casual | I26: S | J26: 5.95 | K26: 3.99 | L26: 10.54 | M26: 0 | N26: 0 | O26: 0.47 | P26: 0.6 | R26: STRIPE | S26: 46030 | T26: 46032 | U26: Tops | V26: David Garcia | W26: 232 Nicole Burg Apt. 563 | Y26: Erikville | Z26: OH | AA26: 50641 | AB26: US | AF26: =IF(OR(A26="",C26=""),"",A26-C26) -> 19 | AG26: =IF(A26="","",IF(D26="No",IFERROR(K26*1,0),IF(D26="Yes",IFERROR(K26/E26,0),""))) -> 3.99 | AH26: =IF(A26="","",IFERROR(N26*1,0)+IFERROR(O26*1,0)+IFERROR(P26*1,0)+IFERROR(Q26*1,0)) -> 1.07 | AI26: {=IF(A26="","",IFERROR(INDEX(Listings!A:A,MATCH(TEXT(C26,"MM/DD/YYYY")&G26&U26,Listings!J$2:J$201,0)+1),""))} -> 29
A27: 46032 | B27: 07:26 AM | C27: 46031 | D27: No | F27: elizabeth_miller | G27: Zara | H27: Zara red cropped oversized top in size s #grunge #vintage #casual #cottagecore #streetwear | I27: S | J27: 18 | K27: 11.99 | L27: 31.79 | M27: 0 | N27: 0 | O27: 1.42 | P27: 1.8 | R27: STRIPE | S27: 46034 | T27: 46036 | U27: Tops | V27: Ms. Susan Vargas | W27: 72046 Lewis Islands Suite 646 | Y27: Maryfort | Z27: NY | AA27: 03041 | AB27: US | AC27: 0.73 | AF27: =IF(OR(A27="",C27=""),"",A27-C27) -> 1 | AG27: =IF(A27="","",IF(D27="No",IFERROR(K27*1,0),IF(D27="Yes",IFERROR(K27/E27,0),""))) -> 11.99 | AH27: =IF(A27="","",IFERROR(N27*1,0)+IFERROR(O27*1,0)+IFERROR(P27*1,0)+IFERROR(Q27*1,0)) -> 3.22 | AI27: {=IF(A27="","",IFERROR(INDEX(Listings!A:A,MATCH(TEXT(C27,"MM/DD/YYYY")&G27&U27,Listings!J$2:J$201,0)+1),""))} -> 45
A28: 46037 | B28: 12:40 PM | C28: 46015 | D28: No | F28: shelbywear | G28: H&M | H28: H&M olive swim cover-up in size m #minimalist #aesthetic #preppy #thrift | I28: M | J28: 7.2 | K28: 7.99 | L28: 15.91 | M28: 0 | N28: 0 | O28: 0.57 | P28: 0.72 | R28: STRIPE | S28: 46039 | T28: 46042 | U28: Swimwear | V28: Renee Mcdaniel | W28: 6159 Alvarado Crossing | Y28: Williamchester | Z28: TX | AA28: 43254 | AB28: US | AC28: 0.69 | AF28: =IF(OR(A28="",C28=""),"",A28-C28) -> 22 | AG28: =IF(A28="","",IF(D28="No",IFERROR(K28*1,0),IF(D28="Yes",IFERROR(K28/E28,0),""))) -> 7.99 | AH28: =IF(A28="","",IFERROR(N28*1,0)+IFERROR(O28*1,0)+IFERROR(P28*1,0)+IFERROR(Q28*1,0)) -> 1.29 | AI28: {=IF(A28="","",IFERROR(INDEX(Listings!A:A,MATCH(TEXT(C28,"MM/DD/YYYY")&G28&U28,Listings!J$2:J$201,0)+1),""))} -> 34
A29: 46039 | B29: 06:10 PM | C29: 46030 | D29: No | F29: jeffrey77 | G29: J.Crew | H29: J.Crew white cotton top in size l #y2k #cottagecore | I29: L | J29: 23 | K29: 7.99 | L29: 33.29 | M29: 0 | N29: 0 | O29: 1.82 | P29: 2.3 | R29: STRIPE | S29: 46041 | T29: 46044 | U29: Tops | V29: Kimberly Morrison | W29: 6706 Caldwell Union | Y29: Ramseymouth | Z29: PA | AA29: 17229 | AB29: US | AC29: 1.67 | AF29: =IF(OR(A29="",C29=""),"",A29-C29) -> 9 | AG29: =IF(A29="","",IF(D29="No",IFERROR(K29*1,0),IF(D29="Yes",IFERROR(K29/E29,0),""))) -> 7.99 | AH29: =IF(A29="","",IFERROR(N29*1,0)+IFERROR(O29*1,0)+IFERROR(P29*1,0)+IFERROR(Q29*1,0)) -> 4.12 | AI29: {=IF(A29="","",IFERROR(INDEX(Listings!A:A,MATCH(TEXT(C29,"MM/DD/YYYY")&G29&U29,Listings!J$2:J$201,0)+1),""))} -> 44
A30: 46041 | B30: 05:58 PM | C30: 46024 | D30: No | F30: jonathonwri | G30: Gap | H30: Gap burgundy wide leg pants in size s #boho #retro | I30: S | J30: 22 | K30: 5.99 | L30: 30.19 | M30: 0 | N30: 0 | O30: 1.74 | P30: 2.2 | R30: STRIPE | S30: 46043 | T30: 46046 | U30: Bottoms | V30: Natasha Wells | W30: 734 Jones Heights Apt. 455 | Y30: East Edwardfurt | Z30: TX | AA30: 91458 | AB30: US | AC30: 1.17 | AF30: =IF(OR(A30="",C30=""),"",A30-C30) -> 17 | AG30: =IF(A30="","",IF(D30="No",IFERROR(K30*1,0),IF(D30="Yes",IFERROR(K30/E30,0),""))) -> 5.99 | AH30: =IF(A30="","",IFERROR(N30*1,0)+IFERROR(O30*1,0)+IFERROR(P30*1,0)+IFERROR(Q30*1,0)) -> 3.94 | AI30: {=IF(A30="","",IFERROR(INDEX(Listings!A:A,MATCH(TEXT(C30,"MM/DD/YYYY")&G30&U30,Listings!J$2:J$201,0)+1),""))} -> 42
A31: 46045 | B31: 06:17 PM | C31: 46035 | D31: No | F31: jonathanwoo | G31: Zara | H31: Zara navy fitted sweater in size s #cottagecore #y2k #preppy #vintage | I31: S | J31: 12.75 | K31: 3.99 | L31: 18.02 | M31: 0 | N31: 0 | O31: 1.01 | P31: 1.28 | R31: STRIPE | S31: 46047 | T31: 46050 | U31: Tops | V31: Travis Marshall | W31: 41904 Sanders Stravenue | Y31: North Brittany | Z31: WA | AA31: 82714 | AB31: US | AC31: 0.7 | AF31: =IF(OR(A31="",C31=""),"",A31-C31) -> 10 | AG31: =IF(A31="","",IF(D31="No",IFERROR(K31*1,0),IF(D31="Yes",IFERROR(K31/E31,0),""))) -> 3.99 | AH31: =IF(A31="","",IFERROR(N31*1,0)+IFERROR(O31*1,0)+IFERROR(P31*1,0)+IFERROR(Q31*1,0)) -> 2.29 | AI31: {=IF(A31="","",IFERROR(INDEX(Listings!A:A,MATCH(TEXT(C31,"MM/DD/YYYY")&G31&U31,Listings!J$2:J$201,0)+1),""))} -> 49
A32: 46046 | B32: 01:25 PM | C32: 46022 | D32: Yes | E32: 2 | F32: davidwear | G32: The North Face | H32: The North Face navy wide leg pants in size l #boho #preppy #grunge #retro | I32: L | J32: 18.75 | K32: 7.99 | L32: 51.39 | M32: 0 | N32: 0 | O32: 3.12 | P32: 3.95 | R32: STRIPE | S32: 46048 | T32: 46051 | U32: Bottoms | V32: Justin Lowery | W32: 8895 Salazar Stravenue | Y32: Rivasside | Z32: LA | AA32: 58947 | AB32: US | AF32: =IF(OR(A32="",C32=""),"",A32-C32) -> 24 | AG32: =IF(A32="","",IF(D32="No",IFERROR(K32*1,0),IF(D32="Yes",IFERROR(K32/E32,0),""))) -> 3.995 | AH32: =IF(A32="","",IFERROR(N32*1,0)+IFERROR(O32*1,0)+IFERROR(P32*1,0)+IFERROR(Q32*1,0)) -> 7.07 | AI32: {=IF(A32="","",IFERROR(INDEX(Listings!A:A,MATCH(TEXT(C32,"MM/DD/YYYY")&G32&U32,Listings!J$2:J$201,0)+1),""))} -> 40
A33: 46046 | B33: 01:25 PM | C33: 46023 | D33: Yes | F33: davidwear | G33: Hollister | H33: Hollister burgundy graphic tee in size xs #vintage #aesthetic #boho | I33: XS | J33: 20.7 | N33: 0 | R33: STRIPE | S33: 46048 | T33: 46051 | U33: Tops | V33: Justin Lowery | W33: 8895 Salazar Stravenue | Y33: Rivasside | Z33: LA | AA33: 58947 | AB33: US | AF33: =IF(OR(A33="",C33=""),"",A33-C33) -> 23 | AG33: =IF(A33="","",IF(D33="No",IFERROR(K33*1,0),IF(D33="Yes",IFERROR(K33/E33,0),""))) -> 0 | AH33: =IF(A33="","",IFERROR(N33*1,0)+IFERROR(O33*1,0)+IFERROR(P33*1,0)+IFERROR(Q33*1,0)) -> 0 | AI33: {=IF(A33="","",IFERROR(INDEX(Listings!A:A,MATCH(TEXT(C33,"MM/DD/YYYY")&G33&U33,Listings!J$2:J$201,0)+1),""))} -> 41
A34: 46046 | B34: 07:00 AM | C34: 46032 | D34: Yes | E34: 2 | F34: thriftjeffrey | G34: Other | H34: Other purple cargo pants in size m #preppy #thrift #y2k #cottagecore #retro | I34: M | J34: 29 | K34: 6.49 | L34: 52.69 | M34: 0 | N34: 0 | O34: 3.32 | P34: 4.2 | R34: STRIPE | S34: 46048 | T34: 46050 | U34: Bottoms | V34: Amy Crane | W34: 003 Mary Road | Y34: East David | Z34: CA | AA34: 88248 | AB34: US | AC34: 1.64 | AF34: =IF(OR(A34="",C34=""),"",A34-C34) -> 14 | AG34: =IF(A34="","",IF(D34="No",IFERROR(K34*1,0),IF(D34="Yes",IFERROR(K34/E34,0),""))) -> 3.245 | AH34: =IF(A34="","",IFERROR(N34*1,0)+IFERROR(O34*1,0)+IFERROR(P34*1,0)+IFERROR(Q34*1,0)) -> 7.52 | AI34: {=IF(A34="","",IFERROR(INDEX(Listings!A:A,MATCH(TEXT(C34,"MM/DD/YYYY")&G34&U34,Listings!J$2:J$201,0)+1),""))} -> 47
A35: 46046 | B35: 07:00 AM | C35: 46033 | D35: Yes | F35: thriftjeffrey | G35: Nike | H35: Nike black ribbed bikini top in size m #y2k #grunge | I35: M | J35: 13 | N35: 0 | R35: STRIPE | S35: 46048 | T35: 46050 | U35: Swimwear | V35: Amy Crane | W35: 003 Mary Road | Y35: East David | Z35: CA | AA35: 88248 | AB35: US | AF35: =IF(OR(A35="",C35=""),"",A35-C35) -> 13 | AG35: =IF(A35="","",IF(D35="No",IFERROR(K35*1,0),IF(D35="Yes",IFERROR(K35/E35,0),""))) -> 0 | AH35: =IF(A35="","",IFERROR(N35*1,0)+IFERROR(O35*1,0)+IFERROR(P35*1,0)+IFERROR(Q35*1,0)) -> 0 | AI35: {=IF(A35="","",IFERROR(INDEX(Listings!A:A,MATCH(TEXT(C35,"MM/DD/YYYY")&G35&U35,Listings!J$2:J$201,0)+1),""))} -> 48
A36: 46046 | B36: 07:24 PM | C36: 46044 | D36: No | F36: gabriellefinds | G36: Abercrombie & Fitch | H36: Abercrombie & Fitch black bodycon dress in size s #retro #vintage | I36: S | J36: 19 | K36: 3.99 | L36: 24.89 | M36: 0 | N36: 0 | O36: 1.5 | P36: 1.9 | R36: STRIPE | S36: 46048 | T36: 46052 | U36: Dresses | V36: Michael Turner | W36: 058 Stanley Cliff | Y36: Alexanderchester | Z36: CA | AA36: 64752 | AB36: US | AC36: 0.85 | AF36: =IF(OR(A36="",C36=""),"",A36-C36) -> 2 | AG36: =IF(A36="","",IF(D36="No",IFERROR(K36*1,0),IF(D36="Yes",IFERROR(K36/E36,0),""))) -> 3.99 | AH36: =IF(A36="","",IFERROR(N36*1,0)+IFERROR(O36*1,0)+IFERROR(P36*1,0)+IFERROR(Q36*1,0)) -> 3.4 | AI36: {=IF(A36="","",IFERROR(INDEX(Listings!A:A,MATCH(TEXT(C36,"MM/DD/YYYY")&G36&U36,Listings!J$2:J$201,0)+1),""))} -> 51
A37: 46050 | B37: 10:17 PM | C37: 46046 | D37: No | F37: maria_zimmerman | G37: Urban Outfitters | H37: Urban Outfitters burgundy maxi dress in size s #thrift #grunge | I37: S | J37: 24 | K37: 3.99 | L37: 30.39 | M37: 0 | N37: 0 | O37: 1.9 | P37: 2.4 | R37: STRIPE | S37: 46052 | T37: 46056 | U37: Dresses | V37: Tyler Reid | W37: 84987 Graham Street Suite 531 | Y37: Nicolebury | Z37: IA | AA37: 98867 | AB37: US | AF37: =IF(OR(A37="",C37=""),"",A37-C37) -> 4 | AG37: =IF(A37="","",IF(D37="No",IFERROR(K37*1,0),IF(D37="Yes",IFERROR(K37/E37,0),""))) -> 3.99 | AH37: =IF(A37="","",IFERROR(N37*1,0)+IFERROR(O37*1,0)+IFERROR(P37*1,0)+IFERROR(Q37*1,0)) -> 4.3 | AI37: {=IF(A37="","",IFERROR(INDEX(Listings!A:A,MATCH(TEXT(C37,"MM/DD/YYYY")&G37&U37,Listings!J$2:J$201,0)+1),""))} -> 53
A38: 46051 | B38: 08:18 PM | C38: 46026 | D38: No | F38: mark_owens | G38: Other | H38: Other gray joggers in size xs #boho #streetwear #cottagecore #minimalist | I38: XS | J38: 18 | K38: 5.99 | L38: 25.79 | M38: 0 | N38: 0 | O38: 1.42 | P38: 1.8 | R38: STRIPE | S38: 46053 | T38: 46055 | U38: Bottoms | V38: Daniel Perry | W38: 66909 Woods Knoll | Y38: Karenchester | Z38: WA | AA38: 71046 | AB38: US | AC38: 0.99 | AF38: =IF(OR(A38="",C38=""),"",A38-C38) -> 25 | AG38: =IF(A38="","",IF(D38="No",IFERROR(K38*1,0),IF(D38="Yes",IFERROR(K38/E38,0),""))) -> 5.99 | AH38: =IF(A38="","",IFERROR(N38*1,0)+IFERROR(O38*1,0)+IFERROR(P38*1,0)+IFERROR(Q38*1,0)) -> 3.22 | AI38: {=IF(A38="","",IFERROR(INDEX(Listings!A:A,MATCH(TEXT(C38,"MM/DD/YYYY")&G38&U38,Listings!J$2:J$201,0)+1),""))} -> 43
A39: 46053 | B39: 01:37 PM | C39: 46052 | D39: No | F39: anthonyros | G39: Victoria's Secret | H39: Victoria's Secret floral denim scarf in size s #casual #aesthetic #cottagecore | I39: S | J39: 6 | K39: 11.99 | L39: 18.59 | M39: 0 | N39: 0 | O39: 0.47 | P39: 0.6 | R39: STRIPE | S39: 46055 | T39: 46058 | U39: Accessories | V39: Leonard Gray | W39: 3545 Beard Squares | Y39: Angelahaven | Z39: IA | AA39: 25543 | AB39: US | AF39: =IF(OR(A39="",C39=""),"",A39-C39) -> 1 | AG39: =IF(A39="","",IF(D39="No",IFERROR(K39*1,0),IF(D39="Yes",IFERROR(K39/E39,0),""))) -> 11.99 | AH39: =IF(A39="","",IFERROR(N39*1,0)+IFERROR(O39*1,0)+IFERROR(P39*1,0)+IFERROR(Q39*1,0)) -> 1.07 | AI39: {=IF(A39="","",IFERROR(INDEX(Listings!A:A,MATCH(TEXT(C39,"MM/DD/YYYY")&G39&U39,Listings!J$2:J$201,0)+1),""))} -> 57
A40: 46076 | B40: 09:49 AM | C40: 46062 | D40: No | F40: jeremywhi | G40: Free People | H40: Free People burgundy athletic blouse in size l #minimalist #cottagecore #thrift #aesthetic #grunge | I40: L | J40: 19 | K40: 4.99 | L40: 25.89 | M40: 0 | N40: 0 | O40: 1.5 | P40: 1.9 | R40: STRIPE | S40: 46078 | T40: 46082 | U40: Tops | V40: Brian Lee | W40: 824 Terri Plaza | Y40: Heidiberg | Z40: NY | AA40: 84107 | AB40: US | AF40: =IF(OR(A40="",C40=""),"",A40-C40) -> 14 | AG40: =IF(A40="","",IF(D40="No",IFERROR(K40*1,0),IF(D40="Yes",IFERROR(K40/E40,0),""))) -> 4.99 | AH40: =IF(A40="","",IFERROR(N40*1,0)+IFERROR(O40*1,0)+IFERROR(P40*1,0)+IFERROR(Q40*1,0)) -> 3.4 | AI40: {=IF(A40="","",IFERROR(INDEX(Listings!A:A,MATCH(TEXT(C40,"MM/DD/YYYY")&G40&U40,Listings!J$2:J$201,0)+1),""))} -> 64
...

Sheet DepopSalesImport
A1: Date of sale | B1: Time of sale | C1: Date of listing | D1: Bundle | E1: Bundle - amount of items | F1: Buyer | G1: Brand | H1: Description | I1: Size | J1: Item price | K1: Buyer shipping cost | L1: Total | M1: USPS Cost | N1: Depop fee | O1: Depop Payments fee | P1: Buyer Marketplace Fee | Q1: Boosting fee | R1: Payment type | S1: Estimated payout date | T1: Payout arrival date | U1: Category | V1: Name | W1: Address Line 1 | X1: Address Line 2 | Y1: City | Z1: State | AA1: Post Code | AB1: Country | AC1: US Sales tax | AD1: Refunded to buyer amount | AE1: Fees refunded to seller
A2: 46123 | B2: 10:51 PM | C2: 46117 | D2: No | F2: adam54 | G2: Express | H2: Express navy y2k bottom in size m #y2k #navy #thrift #depop | I2: M | J2: 17.3 | K2: 4.99 | L2: 24.02 | M2: 0 | N2: 0 | O2: 1.37 | P2: 1.73 | R2: STRIPE | S2: 46125 | T2: 46128 | U2: Bottoms | V2: Cheryl Ortega | W2: 463 Valencia Key | Y2: Smithhaven | Z2: FL | AA2: 70198 | AB2: US | AC2: 0.97
A3: 46125 | B3: 12:30 PM | C3: 46100 | D3: No | F3: nthomas | G3: LOFT | H3: LOFT navy athletic accessorie in size l #athletic #navy #thrift #depop | I3: L | J3: 24.81 | K3: 3.99 | L3: 31.28 | M3: 0 | N3: 0 | O3: 1.96 | P3: 2.48 | R3: STRIPE | S3: 46127 | T3: 46130 | U3: Accessories | V3: Emma Porter | W3: 1521 Smith Village | Y3: West Javierfurt | Z3: OR | AA3: 44640 | AB3: US
A4: 46125 | B4: 2:24 PM | C4: 46113 | D4: No | F4: oarmstrong | G4: Other | H4: Other white lace bottom in size m #lace #white #thrift #depop | I4: M | J4: 26.62 | K4: 4.99 | L4: 34.27 | M4: 0 | N4: 0 | O4: 2.1 | P4: 2.66 | R4: STRIPE | S4: 46127 | T4: 46130 | U4: Bottoms | V4: Karen Jackson | W4: 378 Danny Underpass | Y4: Jonestown | Z4: IL | AA4: 75161 | AB4: US | AC4: 2.01
A5: 46126 | B5: 8:22 AM | C5: 46106 | D5: No | F5: derek63 | G5: Free People | H5: Free People green athletic coats/jacket in size s #athletic #green #thrift #depop | I5: S | J5: 7.42 | K5: 7.99 | L5: 16.15 | M5: 0 | N5: 0 | O5: 0.59 | P5: 0.74 | R5: STRIPE | S5: 46128 | T5: 46131 | U5: Coats/Jackets | V5: Valerie Bowman | W5: 8625 Nielsen Curve Apt. 961 | Y5: North Douglasburgh | Z5: NY | AA5: 23785 | AB5: US | AC5: 0.52
A6: 46128 | B6: 7:33 PM | C6: 46113 | D6: No | F6: mjames | G6: Old Navy | H6: Old Navy pink y2k swimwear in size s #y2k #pink #thrift #depop | I6: S | J6: 9 | K6: 3.99 | L6: 13.89 | M6: 0 | N6: 0 | O6: 0.71 | P6: 0.9 | R6: STRIPE | S6: 46130 | T6: 46133 | U6: Swimwear | V6: David Wolf | W6: 688 Shawna Overpass Apt. 699 | Y6: Port Rachel | Z6: OR | AA6: 49519 | AB6: US
A7: 46129 | B7: 3:27 PM | C7: 46102 | D7: No | F7: cynthia95 | G7: Express | H7: Express blue vintage coats/jacket in size l #vintage #blue #thrift #depop | I7: L | J7: 20.09 | K7: 5.99 | L7: 28.09 | M7: 0 | N7: 0 | O7: 1.59 | P7: 2.01 | R7: STRIPE | S7: 46131 | T7: 46134 | U7: Coats/Jackets | V7: Christopher Chapman | W7: 0058 Angela Highway | Y7: Port Scott | Z7: IL | AA7: 91666 | AB7: US | AC7: 1.34
A8: 46132 | B8: 11:38 AM | C8: 46123 | D8: No | F8: khanrobert | G8: Zara | H8: Zara gray y2k dresse in size xl #y2k #gray #thrift #depop | I8: XL | J8: 15.61 | K8: 6.49 | L8: 23.66 | M8: 0 | N8: 0 | O8: 1.23 | P8: 1.56 | R8: STRIPE | S8: 46134 | T8: 46137 | U8: Dresses | V8: Andrea Carter | W8: 8246 Ortiz Shoals Apt. 469 | Y8: Leemouth | Z8: OH | AA8: 26408 | AB8: US | AC8: 0.73
